Script started on 2025-08-22 18:03:32-04:00 [COMMAND="set -x && python issue/phase-2/test_runner.py" TERM="screen.xterm-256color" TTY="/dev/pty3" COLUMNS="131" LINES="44"]
+ python issue/phase-2/test_runner.py
============================================================
PHASE 2 TEST RUNNER: Network Connections Implementation
============================================================
Phase 2 Network Connection Tests:
----------------------------------------
üìã TestBasicOperations.test_process
üìã TestBasicOperations.test_system
üìã TestUnconnectedSockets.test_tcp_v4
üìã TestUnconnectedSockets.test_tcp_v6
üìã TestUnconnectedSockets.test_udp_v4
üìã TestUnconnectedSockets.test_udp_v6
üìã TestUnconnectedSockets.test_unix_tcp
üìã TestUnconnectedSockets.test_unix_udp
üìã TestConnectedSocket.test_tcp
üìã TestConnectedSocket.test_unix
üìã TestSystemWideConnections.test_it
‚ùå Could not find test: TestSystemWideConnections.test_duplicate_address - 'TestSystemWideConnections' object has no attribute 'test_duplicate_address'
‚ùå Could not find test: TestSystemWideConnections.test_families - 'TestSystemWideConnections' object has no attribute 'test_families'
‚ùå Could not find test: TestSystemWideConnections.test_combos - 'TestSystemWideConnections' object has no attribute 'test_combos'
‚ùå Could not find test: TestProcessConnections.test_proc_net_connections - module 'test_connections' has no attribute 'TestProcessConnections'
‚ùå Could not find test: TestProcessConnections.test_proc_net_connections_reuse_address - module 'test_connections' has no attribute 'TestProcessConnections'
Running Phase 2 Tests...
----------------------------------------
unittest.case.FunctionTestCase (test_process) ... ok
unittest.case.FunctionTestCase (test_system) ... ok
unittest.case.FunctionTestCase (test_tcp_v4) ... FAIL
unittest.case.FunctionTestCase (test_tcp_v6) ... FAIL
unittest.case.FunctionTestCase (test_udp_v4) ... FAIL
unittest.case.FunctionTestCase (test_udp_v6) ... FAIL
unittest.case.FunctionTestCase (test_unix_tcp) ... FAIL
unittest.case.FunctionTestCase (test_unix_udp) ... FAIL
unittest.case.FunctionTestCase (test_tcp) ... FAIL
unittest.case.FunctionTestCase (test_unix) ... ERROR
unittest.case.FunctionTestCase (test_it) ... ok
======================================================================
ERROR: unittest.case.FunctionTestCase (test_unix)
----------------------------------------------------------------------
Traceback (most recent call last):
  File "/home/phdyex/my-repos/psutil/issue/phase-2/../../psutil/tests/test_connections.py", line 232, in test_unix
    assert not (cons[0].laddr and cons[0].raddr), cons
IndexError: list index out of range
======================================================================
FAIL: unittest.case.FunctionTestCase (test_tcp_v4)
----------------------------------------------------------------------
Traceback (most recent call last):
  File "/home/phdyex/my-repos/psutil/issue/phase-2/../../psutil/tests/test_connections.py", line 154, in test_tcp_v4
    conn = self.check_socket(sock)
  File "/home/phdyex/my-repos/psutil/issue/phase-2/../../psutil/tests/test_connections.py", line 126, in check_socket
    conn = self.get_conn_from_sock(sock)
  File "/home/phdyex/my-repos/psutil/issue/phase-2/../../psutil/tests/test_connections.py", line 116, in get_conn_from_sock
    assert len(cons) == 1
AssertionError
======================================================================
FAIL: unittest.case.FunctionTestCase (test_tcp_v6)
----------------------------------------------------------------------
Traceback (most recent call last):
  File "/home/phdyex/my-repos/psutil/issue/phase-2/../../psutil/tests/test_connections.py", line 162, in test_tcp_v6
    conn = self.check_socket(sock)
  File "/home/phdyex/my-repos/psutil/issue/phase-2/../../psutil/tests/test_connections.py", line 126, in check_socket
    conn = self.get_conn_from_sock(sock)
  File "/home/phdyex/my-repos/psutil/issue/phase-2/../../psutil/tests/test_connections.py", line 116, in get_conn_from_sock
    assert len(cons) == 1
AssertionError
======================================================================
FAIL: unittest.case.FunctionTestCase (test_udp_v4)
----------------------------------------------------------------------
Traceback (most recent call last):
  File "/home/phdyex/my-repos/psutil/issue/phase-2/../../psutil/tests/test_connections.py", line 169, in test_udp_v4
    conn = self.check_socket(sock)
  File "/home/phdyex/my-repos/psutil/issue/phase-2/../../psutil/tests/test_connections.py", line 126, in check_socket
    conn = self.get_conn_from_sock(sock)
  File "/home/phdyex/my-repos/psutil/issue/phase-2/../../psutil/tests/test_connections.py", line 116, in get_conn_from_sock
    assert len(cons) == 1
AssertionError
======================================================================
FAIL: unittest.case.FunctionTestCase (test_udp_v6)
----------------------------------------------------------------------
Traceback (most recent call last):
  File "/home/phdyex/my-repos/psutil/issue/phase-2/../../psutil/tests/test_connections.py", line 177, in test_udp_v6
    conn = self.check_socket(sock)
  File "/home/phdyex/my-repos/psutil/issue/phase-2/../../psutil/tests/test_connections.py", line 126, in check_socket
    conn = self.get_conn_from_sock(sock)
  File "/home/phdyex/my-repos/psutil/issue/phase-2/../../psutil/tests/test_connections.py", line 116, in get_conn_from_sock
    assert len(cons) == 1
AssertionError
======================================================================
FAIL: unittest.case.FunctionTestCase (test_unix_tcp)
----------------------------------------------------------------------
Traceback (most recent call last):
  File "/home/phdyex/my-repos/psutil/issue/phase-2/../../psutil/tests/test_connections.py", line 185, in test_unix_tcp
    conn = self.check_socket(sock)
  File "/home/phdyex/my-repos/psutil/issue/phase-2/../../psutil/tests/test_connections.py", line 126, in check_socket
    conn = self.get_conn_from_sock(sock)
  File "/home/phdyex/my-repos/psutil/issue/phase-2/../../psutil/tests/test_connections.py", line 116, in get_conn_from_sock
    assert len(cons) == 1
AssertionError
======================================================================
FAIL: unittest.case.FunctionTestCase (test_unix_udp)
----------------------------------------------------------------------
Traceback (most recent call last):
  File "/home/phdyex/my-repos/psutil/issue/phase-2/../../psutil/tests/test_connections.py", line 193, in test_unix_udp
    conn = self.check_socket(sock)
  File "/home/phdyex/my-repos/psutil/issue/phase-2/../../psutil/tests/test_connections.py", line 126, in check_socket
    conn = self.get_conn_from_sock(sock)
  File "/home/phdyex/my-repos/psutil/issue/phase-2/../../psutil/tests/test_connections.py", line 116, in get_conn_from_sock
    assert len(cons) == 1
AssertionError
======================================================================
FAIL: unittest.case.FunctionTestCase (test_tcp)
----------------------------------------------------------------------
Traceback (most recent call last):
  File "/home/phdyex/my-repos/psutil/issue/phase-2/../../psutil/tests/test_connections.py", line 213, in test_tcp
    assert len(cons) == 2
AssertionError
----------------------------------------------------------------------
Ran 11 tests in 1.118s
FAILED (failures=7, errors=1)
============================================================
PHASE 2 RESULTS
============================================================
‚ùå PHASE 2 INCOMPLETE
‚ùå 7 test failures
‚ùå 1 test errors
üìä 8/16 tests passed
Failures:
  ‚Ä¢ unittest.case.FunctionTestCase (test_tcp_v4)
  ‚Ä¢ unittest.case.FunctionTestCase (test_tcp_v6)
  ‚Ä¢ unittest.case.FunctionTestCase (test_udp_v4)
  ‚Ä¢ unittest.case.FunctionTestCase (test_udp_v6)
  ‚Ä¢ unittest.case.FunctionTestCase (test_unix_tcp)
  ‚Ä¢ unittest.case.FunctionTestCase (test_unix_udp)
  ‚Ä¢ unittest.case.FunctionTestCase (test_tcp)
Errors:
  ‚Ä¢ unittest.case.FunctionTestCase (test_unix)
Remaining work needed for Phase 2 completion.
Script done on 2025-08-22 18:03:36-04:00 [COMMAND_EXIT_CODE="1"]

